<robot xmlns:xacro="http://ros.org/wiki/xacro"
        xmlns:sensor="http://playerstage.sourceforge.net/gazebo/xmlschema/#sensor"
       xmlns:controller="http://playerstage.sourceforge.net/gazebo/xmlschema/#controller"
       xmlns:joint="http://playerstage.sourceforge.net/gazebo/xmlschema/#slider"
       xmlns:interface="http://playerstage.sourceforge.net/gazebo/xmlschema/#interface"
       xmlns:body="http://playerstage.sourceforge.net/gazebo/xmlschema/#body"
       xmlns:geom="http://playerstage.sourceforge.net/gazebo/xmlschema/#geom">

  <include filename="$(find sr_description)/hand/xacro/finger/knuckle/knuckle.transmission.xacro" />

  <xacro:macro name="knuckle" params="link_prefix joint_prefix parent *origin">

    <link name="${link_prefix}knuckle">
      <inertial>
	<origin xyz="0 0 0" rpy="0 0 0" />
	<!--<insert_block name="origin" /> -->
	<mass value="0.008" />
	<inertia  ixx="0.0" ixy="0.0"  ixz="0.0"  iyy="0.1"  iyz="0.0"
	izz="0.0" />
      </inertial>
      <visual>
	<origin xyz="0 0 0.0005" rpy="0 0 0" />
	<geometry name="knuckle_visual">
      <mesh filename="package://sr_description/hand/model/knuckle.dae" scale="0.001 0.001 0.001" />
      </geometry>
      <material name="LightGrey" />
      </visual>
      <collision>
	<origin xyz="0 0 0" rpy="0 0 0" />
	<geometry name="knuckle_collision_geom">
	  <box size="0.005 0.005 0.005" />
	</geometry>
      </collision>
    </link>
    <gazebo reference="${link_prefix}knuckle">
      <sensor:contact name="${link_prefix}knuckle_contact_sensor">
        <geom>${link_prefix}knuckle_geom</geom>
       <updateRate>100.0</updateRate>
        <controller:gazebo_ros_bumper name="${link_prefix}knuckle_gazebo_ros_bumper_controller" plugin="libgazebo_ros_bumper.so">
          <alwaysOn>true</alwaysOn>
          <updateRate>100.0</updateRate>
          <frameName>${link_prefix}knuckle</frameName>
          <bumperTopicName>${link_prefix}knuckle_bumper</bumperTopicName>
          <interface:bumper name="${link_prefix}knuckle_gazebo_ros_bumper_iface" />
        </controller:gazebo_ros_bumper>
      </sensor:contact>
      <material>PR2/Grey2</material>
    </gazebo>

    <joint name="${joint_prefix}J4" type="revolute">
      <parent link="${parent}"/>
      <child link="${link_prefix}knuckle"/>
      <!--<origin xyz="0.033 0 0.095" rpy="0 0 0" />-->
      <insert_block name="origin" />
      <insert_block name="axis"/>
      <limit lower="-0.3491" upper="0.3491"
      effort="10" velocity="1.0"/>
      <dynamics damping="50.5"/>
    </joint>

    <xacro:knuckle_transmission />

  </xacro:macro>

</robot>
