<robot xmlns:xacro="http://ros.org/wiki/xacro"
	xmlns:sensor="http://playerstage.sourceforge.net/gazebo/xmlschema/#sensor"
	xmlns:controller="http://playerstage.sourceforge.net/gazebo/xmlschema/#controller"
       xmlns:joint="http://playerstage.sourceforge.net/gazebo/xmlschema/#slider"
       xmlns:interface="http://playerstage.sourceforge.net/gazebo/xmlschema/#interface"
       xmlns:body="http://playerstage.sourceforge.net/gazebo/xmlschema/#body"
       xmlns:geom="http://playerstage.sourceforge.net/gazebo/xmlschema/#geom">

  <xacro:include filename="$(find sr_description)/hand/xacro/finger/distal/distal.transmission.xacro" />

  <xacro:macro name="distal" params="link_prefix joint_prefix parent">

    <link name="${link_prefix}distal">
      <inertial>
	<mass value="0.010" />
	<origin xyz="0 0 0.013" />
	<inertia  ixx="0.1" ixy="0.0"  ixz="0.0"  iyy="0.1"  iyz="0.0"
	izz="0.0" />
      </inertial>
      <visual>
	<origin xyz="0 0 0" rpy="0 0 0" />
	<geometry name="${link_prefix}distal_visual">
      <mesh filename="package://sr_description/hand/model/F1.dae" scale="0.001 0.001 0.001" />
      </geometry>
      <material name="Grey" />
      </visual>
      <collision>
	<origin xyz="0 0 0" rpy="0 0 0" />
	<geometry name="${link_prefix}distal_collision_geom">
	 <mesh filename="package://sr_description/hand/model/F1.dae" scale="0.001 0.001 0.001" />
	</geometry>
      </collision>
    </link>
    <gazebo reference="${link_prefix}distal">
      <sensor type="contact" name="${link_prefix}distal_contact_sensor">
        <update_rate>100.0</update_rate>
        <contact>
          <collision>${link_prefix}distal_collision_geom</collision>
        </contact>
        <plugin name="${link_prefix}distal_gazebo_ros_bumper_controller" filename="libgazebo_ros_bumper.so">
          <alwaysOn>true</alwaysOn>
          <frameName>${link_prefix}distal</frameName>
          <updateRate>100.0</updateRate>
          <bumperTopicName>${link_prefix}distal_bumper</bumperTopicName>
        </plugin>
      </sensor>

      <mu1 value="500.0" />
      <mu2 value="500.0" />
      <kp  value="10000000.0" />
      <kd  value="1.0" />

      <material>Gazebo/Grey</material>
      <selfCollide>true</selfCollide>
    </gazebo>

    <joint name="${joint_prefix}J1" type="revolute">
      <parent link="${parent}"/>
      <child link="${link_prefix}distal"/>
      <origin xyz="0 0 0.025" rpy="0 0 0" />
      <axis xyz="1 0 0" />
      <limit lower="0" upper="${M_PI/2}" effort="1000.0"
      velocity="10.0" />
      <dynamics damping="10.0"/>
    </joint>

    <link name="${link_prefix}tip">
			<inertial>
				<mass value="0.001" />
				<inertia  ixx="0.0" ixy="0.0"  ixz="0.0"  iyy="0.0"  iyz="0.0" izz="0.0" />
  		</inertial>
    </link>
    <joint name="${joint_prefix}tip" type="fixed">
      <parent link="${link_prefix}distal"/>
      <child link="${link_prefix}tip"/>
      <origin xyz="0 0 0.026" rpy="0 0 0" />
    </joint>

<!--
    <xacro:distal_transmission />
-->
  </xacro:macro>

</robot>
