<mujoco model="MuJoCo Model">
    <compiler angle="radian" />
    <option impratio="300" cone="elliptic" />
    <size njmax="1000" nconmax="1000" />
    <visual>
        <global offwidth="800" offheight="800" />
        <quality shadowsize="2048" offsamples="8" />
        <map force="0.1" fogend="5" znear="0.1" />
    </visual>
    <default class="main">
        <mesh scale="0.001 0.001 0.001" />
        <joint limited="true" armature="0.005" damping="0.05" frictionloss="0.1" />
        <default class="collision">
            <geom group="3" />
        </default>
        <default class="visual">
            <geom contype="0" conaffinity="0" />
        </default>
        <default class="finger">
            <joint range="0 1.5708" />
            <default class="FJ4">
                <joint range="-0.349066 0.349066" />
            </default>
        </default>
        <default class="thumb">
            <joint frictionloss="0.001" />
        </default>
    </default>
    <asset>
        <texture type="skybox" builtin="gradient" rgb1="0.4 0.6 0.8" rgb2="0 0 0" width="128" height="768" />
        <texture type="cube" name="texgeom" builtin="flat" mark="cross" rgb1="0.8 0.6 0.4" rgb2="0.8 0.6 0.4" markrgb="1 1 1" width="127" height="762" />
        <texture type="2d" name="texplane" builtin="checker" rgb1="0.2 0.3 0.4" rgb2="0.1 0.15 0.2" width="512" height="512" />
        <material name="mat_plane" texture="texplane" texuniform="true" reflectance="0.3" />
        <material name="block_mat" specular="0" rgba="0.2 0.2 0.2 1" />
        <material name="geom" texture="texgeom" texuniform="true" />
        <material name="metal" specular="1" reflectance="1" rgba="0.6 0.6 0.6 1" />
        <material name="plastic" rgba="0.2 0.2 0.2 1" />
        <material name="rubber" shininess="0" rgba="0.3 0.3 0.3 1" />
        <mesh name="base" file="meshes/arm_and_hand_meshes/visual/base.stl" scale="1 1 1" />
        <mesh name="shoulder" file="meshes/arm_and_hand_meshes/shoulder.stl" scale="1 1 1" />
        <mesh name="upperarm_body_link" file="meshes/arm_and_hand_meshes/upperarm_body.stl" scale="1 1 1" />
        <mesh name="upperarm_bottom_link" file="meshes/arm_and_hand_meshes/upperarm_bottom_link.stl" scale="1 1 1" />
        <mesh name="upperarm_top_link" file="meshes/arm_and_hand_meshes/upperarm_top_link.stl" scale="1 1 1" />
        <mesh name="forearm_body_link" file="meshes/arm_and_hand_meshes/forearm_body_link.stl" scale="1 1 1" />
        <mesh name="forearm_bottom_link" file="meshes/arm_and_hand_meshes/forearm_bottom_link.stl" scale="1 1 1" />
        <mesh name="forearm_top_link" file="meshes/arm_and_hand_meshes/forearm_top_link.stl" scale="1 1 1" />
        <mesh name="wrist1_link" file="meshes/arm_and_hand_meshes/wrist1_link.stl" scale="1 1 1" />
        <mesh name="wrist1_base" file="meshes/arm_and_hand_meshes/wrist1_base.stl" scale="1 1 1" />
        <mesh name="wrist2_link" file="meshes/arm_and_hand_meshes/wrist2_link.stl" scale="1 1 1" />
        <mesh name="wrist2_base" file="meshes/arm_and_hand_meshes/wrist2_base.stl" scale="1 1 1" />
        <mesh name="wrist3" file="meshes/arm_and_hand_meshes/wrist3.stl" scale="1 1 1" />
        <mesh name="mount_link_50_4_M6_col" file="meshes/arm_and_hand_meshes/mount_link_50_4_M6.stl" scale="1 1 1" />
        <mesh name="F1_visual" file="meshes/arm_and_hand_meshes/visual/F1.stl" />
        <mesh name="F1_collision" file="meshes/arm_and_hand_meshes/collision/F1.stl" />
        <mesh name="F2_visual" file="meshes/arm_and_hand_meshes/visual/F2.stl" />
        <mesh name="F2_collision_proximal" file="meshes/arm_and_hand_meshes/collision/decomposed/F2/F2_proximal.stl" />
        <mesh name="F2_collision_middle" file="meshes/arm_and_hand_meshes/collision/decomposed/F2/F2_middle.stl" />
        <mesh name="F2_collision_distal" file="meshes/arm_and_hand_meshes/collision/decomposed/F2/F2_distal.stl" />
        <mesh name="F3_visual" file="meshes/arm_and_hand_meshes/visual/F3.stl" />
        <mesh name="F3_collision_proximal" file="meshes/arm_and_hand_meshes/collision/decomposed/F3/F3_proximal.stl" />
        <mesh name="F3_collision_distal" file="meshes/arm_and_hand_meshes/collision/decomposed/F3/F3_distal.stl" />
        <mesh name="TH1_visual" file="meshes/arm_and_hand_meshes/visual/TH1_z.stl" />
        <mesh name="TH1_collision" file="meshes/arm_and_hand_meshes/collision/TH1.stl" />
        <mesh name="TH2_visual" file="meshes/arm_and_hand_meshes/visual/TH2_z.stl" />
        <mesh name="TH2_collision_proximal" file="meshes/arm_and_hand_meshes/collision/decomposed/TH2/TH2_proximal.stl" />
        <mesh name="TH2_collision_middle" file="meshes/arm_and_hand_meshes/collision/decomposed/TH2/TH2_middle.stl" />
        <mesh name="TH2_collision_distal" file="meshes/arm_and_hand_meshes/collision/decomposed/TH2/TH2_distal.stl" />
        <mesh name="TH3_visual" file="meshes/arm_and_hand_meshes/visual/TH3_z.stl" />
        <mesh name="TH3_collision_proximal" file="meshes/arm_and_hand_meshes/collision/decomposed/TH3/TH3_proximal.stl" />
        <mesh name="TH3_collision_distal" file="meshes/arm_and_hand_meshes/collision/decomposed/TH3/TH3_distal.stl" />
        <mesh name="forearm_visual" file="meshes/arm_and_hand_meshes/visual/forearm.stl" />
        <mesh name="forearm_collision" file="meshes/arm_and_hand_meshes/collision/decomposed/forearm/forearm.stl" />
        <mesh name="forearm_collision_wrist" file="meshes/arm_and_hand_meshes/collision/decomposed/forearm/forearm_wrist.stl" />
        <mesh name="forearm_plus_visual" file="meshes/arm_and_hand_meshes/visual/forearm_plus.stl" />
        <mesh name="forearm_plus_collision_1" file="meshes/arm_and_hand_meshes/collision/decomposed/forearm_plus/forearm_plus_1.stl" />
        <mesh name="forearm_plus_collision_2" file="meshes/arm_and_hand_meshes/collision/decomposed/forearm_plus/forearm_plus_2.stl" />
        <mesh name="forearm_plus_collision_3" file="meshes/arm_and_hand_meshes/collision/decomposed/forearm_plus/forearm_plus_3.stl" />
        <mesh name="forearm_plus_collision_4" file="meshes/arm_and_hand_meshes/collision/decomposed/forearm_plus/forearm_plus_4.stl" />
        <mesh name="forearm_plus_collision_5" file="meshes/arm_and_hand_meshes/collision/decomposed/forearm_plus/forearm_plus_5.stl" />
        <mesh name="knuckle_visual" file="meshes/arm_and_hand_meshes/visual/knuckle.stl" />
        <mesh name="knuckle_collision" file="meshes/arm_and_hand_meshes/collision/knuckle.stl" />
        <mesh name="palm_visual" file="meshes/arm_and_hand_meshes/visual/palm.stl" />
        <mesh name="palm_collision_0" file="meshes/arm_and_hand_meshes/collision/decomposed/palm/palmShape_IndexedFaceSet.stl" />
        <mesh name="palm_collision_1" file="meshes/arm_and_hand_meshes/collision/decomposed/palm/palmShape_IndexedFaceSet_001.stl" />
        <mesh name="palm_collision_2" file="meshes/arm_and_hand_meshes/collision/decomposed/palm/palmShape_IndexedFaceSet_002.stl" />
        <mesh name="palm_collision_3" file="meshes/arm_and_hand_meshes/collision/decomposed/palm/palmShape_IndexedFaceSet_003.stl" />
        <mesh name="palm_collision_4" file="meshes/arm_and_hand_meshes/collision/decomposed/palm/palmShape_IndexedFaceSet_004.stl" />
        <mesh name="palm_collision_5" file="meshes/arm_and_hand_meshes/collision/decomposed/palm/palmShape_IndexedFaceSet_005.stl" />
        <mesh name="palm_collision_6" file="meshes/arm_and_hand_meshes/collision/decomposed/palm/palmShape_IndexedFaceSet_006.stl" />
        <mesh name="palm_collision_7" file="meshes/arm_and_hand_meshes/collision/decomposed/palm/palmShape_IndexedFaceSet_007.stl" />
        <mesh name="palm_collision_8" file="meshes/arm_and_hand_meshes/collision/decomposed/palm/palmShape_IndexedFaceSet_008.stl" />
        <mesh name="palm_collision_9" file="meshes/arm_and_hand_meshes/collision/decomposed/palm/palmShape_IndexedFaceSet_009.stl" />
        <mesh name="palm_collision_10" file="meshes/arm_and_hand_meshes/collision/decomposed/palm/palmShape_IndexedFaceSet_010.stl" />
        <mesh name="palm_collision_11" file="meshes/arm_and_hand_meshes/collision/decomposed/palm/palmShape_IndexedFaceSet_011.stl" />
        <mesh name="palm_collision_12" file="meshes/arm_and_hand_meshes/collision/decomposed/palm/palmShape_IndexedFaceSet_012.stl" />
        <mesh name="palm_collision_13" file="meshes/arm_and_hand_meshes/collision/decomposed/palm/palmShape_IndexedFaceSet_013.stl" />
        <mesh name="palm_collision_14" file="meshes/arm_and_hand_meshes/collision/decomposed/palm/palmShape_IndexedFaceSet_014.stl" />
        <mesh name="palm_collision_15" file="meshes/arm_and_hand_meshes/collision/decomposed/palm/palmShape_IndexedFaceSet_015.stl" />
        <mesh name="palm_collision_16" file="meshes/arm_and_hand_meshes/collision/decomposed/palm/palmShape_IndexedFaceSet_016.stl" />
        <mesh name="palm_collision_17" file="meshes/arm_and_hand_meshes/collision/decomposed/palm/palmShape_IndexedFaceSet_017.stl" />
        <mesh name="palm_collision_18" file="meshes/arm_and_hand_meshes/collision/decomposed/palm/palmShape_IndexedFaceSet_018.stl" />
        <mesh name="palm_collision_19" file="meshes/arm_and_hand_meshes/collision/decomposed/palm/palmShape_IndexedFaceSet_019.stl" />
        <mesh name="palm_collision_20" file="meshes/arm_and_hand_meshes/collision/decomposed/palm/palmShape_IndexedFaceSet_020.stl" />
        <mesh name="palm_collision_21" file="meshes/arm_and_hand_meshes/collision/decomposed/palm/palmShape_IndexedFaceSet_021.stl" />
        <mesh name="palm_collision_22" file="meshes/arm_and_hand_meshes/collision/decomposed/palm/palmShape_IndexedFaceSet_022.stl" />
        <mesh name="palm_collision_23" file="meshes/arm_and_hand_meshes/collision/decomposed/palm/palmShape_IndexedFaceSet_023.stl" />
        <mesh name="palm_collision_24" file="meshes/arm_and_hand_meshes/collision/decomposed/palm/palmShape_IndexedFaceSet_024.stl" />
        <mesh name="palm_collision_25" file="meshes/arm_and_hand_meshes/collision/decomposed/palm/palmShape_IndexedFaceSet_025.stl" />
        <mesh name="palm_collision_26" file="meshes/arm_and_hand_meshes/collision/decomposed/palm/palmShape_IndexedFaceSet_026.stl" />
        <mesh name="palm_collision_27" file="meshes/arm_and_hand_meshes/collision/decomposed/palm/palmShape_IndexedFaceSet_027.stl" />
        <mesh name="palm_collision_28" file="meshes/arm_and_hand_meshes/collision/decomposed/palm/palmShape_IndexedFaceSet_028.stl" />
        <mesh name="palm_collision_29" file="meshes/arm_and_hand_meshes/collision/decomposed/palm/palmShape_IndexedFaceSet_029.stl" />
        <mesh name="palm_collision_30" file="meshes/arm_and_hand_meshes/collision/decomposed/palm/palmShape_IndexedFaceSet_030.stl" />
        <mesh name="palm_collision_31" file="meshes/arm_and_hand_meshes/collision/decomposed/palm/palmShape_IndexedFaceSet_031.stl" />
        <mesh name="palm_collision_32" file="meshes/arm_and_hand_meshes/collision/decomposed/palm/palmShape_IndexedFaceSet_032.stl" />
        <mesh name="palm_collision_33" file="meshes/arm_and_hand_meshes/collision/decomposed/palm/palmShape_IndexedFaceSet_033.stl" />
        <mesh name="palm_collision_34" file="meshes/arm_and_hand_meshes/collision/decomposed/palm/palmShape_IndexedFaceSet_034.stl" />
        <mesh name="palm_collision_35" file="meshes/arm_and_hand_meshes/collision/decomposed/palm/palmShape_IndexedFaceSet_035.stl" />
        <mesh name="palm_collision_36" file="meshes/arm_and_hand_meshes/collision/decomposed/palm/palmShape_IndexedFaceSet_036.stl" />
        <mesh name="palm_collision_37" file="meshes/arm_and_hand_meshes/collision/decomposed/palm/palmShape_IndexedFaceSet_037.stl" />
        <mesh name="palm_collision_38" file="meshes/arm_and_hand_meshes/collision/decomposed/palm/palmShape_IndexedFaceSet_038.stl" />
        <mesh name="palm_collision_39" file="meshes/arm_and_hand_meshes/collision/decomposed/palm/palmShape_IndexedFaceSet_039.stl" />
        <mesh name="palm_collision_40" file="meshes/arm_and_hand_meshes/collision/decomposed/palm/palmShape_IndexedFaceSet_040.stl" />
        <mesh name="palm_collision_41" file="meshes/arm_and_hand_meshes/collision/decomposed/palm/palmShape_IndexedFaceSet_041.stl" />
        <mesh name="palm_collision_42" file="meshes/arm_and_hand_meshes/collision/decomposed/palm/palmShape_IndexedFaceSet_042.stl" />
        <mesh name="palm_collision_43" file="meshes/arm_and_hand_meshes/collision/decomposed/palm/palmShape_IndexedFaceSet_043.stl" />
        <mesh name="palm_collision_44" file="meshes/arm_and_hand_meshes/collision/decomposed/palm/palmShape_IndexedFaceSet_044.stl" />
        <mesh name="palm_collision_45" file="meshes/arm_and_hand_meshes/collision/decomposed/palm/palmShape_IndexedFaceSet_045.stl" />
        <mesh name="palm_collision_46" file="meshes/arm_and_hand_meshes/collision/decomposed/palm/palmShape_IndexedFaceSet_046.stl" />
        <mesh name="palm_collision_47" file="meshes/arm_and_hand_meshes/collision/decomposed/palm/palmShape_IndexedFaceSet_047.stl" />
        <mesh name="palm_collision_48" file="meshes/arm_and_hand_meshes/collision/decomposed/palm/palmShape_IndexedFaceSet_048.stl" />
        <mesh name="palm_collision_49" file="meshes/arm_and_hand_meshes/collision/decomposed/palm/palmShape_IndexedFaceSet_049.stl" />
        <mesh name="palm_collision_50" file="meshes/arm_and_hand_meshes/collision/decomposed/palm/palmShape_IndexedFaceSet_050.stl" />
        <mesh name="palm_collision_51" file="meshes/arm_and_hand_meshes/collision/decomposed/palm/palmShape_IndexedFaceSet_051.stl" />
        <mesh name="palm_collision_52" file="meshes/arm_and_hand_meshes/collision/decomposed/palm/palmShape_IndexedFaceSet_052.stl" />
        <mesh name="palm_collision_53" file="meshes/arm_and_hand_meshes/collision/decomposed/palm/palmShape_IndexedFaceSet_053.stl" />
        <mesh name="palm_collision_54" file="meshes/arm_and_hand_meshes/collision/decomposed/palm/palmShape_IndexedFaceSet_054.stl" />
        <mesh name="palm_collision_55" file="meshes/arm_and_hand_meshes/collision/decomposed/palm/palmShape_IndexedFaceSet_055.stl" />
        <mesh name="palm_collision_56" file="meshes/arm_and_hand_meshes/collision/decomposed/palm/palmShape_IndexedFaceSet_056.stl" />
        <mesh name="palm_collision_57" file="meshes/arm_and_hand_meshes/collision/decomposed/palm/palmShape_IndexedFaceSet_057.stl" />
        <mesh name="palm_collision_58" file="meshes/arm_and_hand_meshes/collision/decomposed/palm/palmShape_IndexedFaceSet_058.stl" />
        <mesh name="palm_collision_59" file="meshes/arm_and_hand_meshes/collision/decomposed/palm/palmShape_IndexedFaceSet_059.stl" />
        <mesh name="palm_collision_60" file="meshes/arm_and_hand_meshes/collision/decomposed/palm/palmShape_IndexedFaceSet_060.stl" />
        <mesh name="palm_collision_61" file="meshes/arm_and_hand_meshes/collision/decomposed/palm/palmShape_IndexedFaceSet_061.stl" />
        <mesh name="palm_collision_62" file="meshes/arm_and_hand_meshes/collision/decomposed/palm/palmShape_IndexedFaceSet_062.stl" />
        <mesh name="palm_collision_63" file="meshes/arm_and_hand_meshes/collision/decomposed/palm/palmShape_IndexedFaceSet_063.stl" />
        <mesh name="palm_collision_64" file="meshes/arm_and_hand_meshes/collision/decomposed/palm/palmShape_IndexedFaceSet_064.stl" />
        <mesh name="palm_collision_65" file="meshes/arm_and_hand_meshes/collision/decomposed/palm/palmShape_IndexedFaceSet_065.stl" />
        <mesh name="palm_collision_66" file="meshes/arm_and_hand_meshes/collision/decomposed/palm/palmShape_IndexedFaceSet_066.stl" />
        <mesh name="palm_collision_67" file="meshes/arm_and_hand_meshes/collision/decomposed/palm/palmShape_IndexedFaceSet_067.stl" />
        <mesh name="palm_collision_68" file="meshes/arm_and_hand_meshes/collision/decomposed/palm/palmShape_IndexedFaceSet_068.stl" />
        <mesh name="palm_collision_69" file="meshes/arm_and_hand_meshes/collision/decomposed/palm/palmShape_IndexedFaceSet_069.stl" />
        <mesh name="palm_collision_70" file="meshes/arm_and_hand_meshes/collision/decomposed/palm/palmShape_IndexedFaceSet_070.stl" />
        <mesh name="palm_collision_71" file="meshes/arm_and_hand_meshes/collision/decomposed/palm/palmShape_IndexedFaceSet_071.stl" />
        <mesh name="palm_collision_72" file="meshes/arm_and_hand_meshes/collision/decomposed/palm/palmShape_IndexedFaceSet_072.stl" />
        <mesh name="palm_collision_73" file="meshes/arm_and_hand_meshes/collision/decomposed/palm/palmShape_IndexedFaceSet_073.stl" />
        <mesh name="palm_collision_74" file="meshes/arm_and_hand_meshes/collision/decomposed/palm/palmShape_IndexedFaceSet_074.stl" />
        <mesh name="palm_collision_75" file="meshes/arm_and_hand_meshes/collision/decomposed/palm/palmShape_IndexedFaceSet_075.stl" />
        <mesh name="palm_collision_76" file="meshes/arm_and_hand_meshes/collision/decomposed/palm/palmShape_IndexedFaceSet_076.stl" />
        <mesh name="palm_collision_77" file="meshes/arm_and_hand_meshes/collision/decomposed/palm/palmShape_IndexedFaceSet_077.stl" />
        <mesh name="palm_collision_78" file="meshes/arm_and_hand_meshes/collision/decomposed/palm/palmShape_IndexedFaceSet_078.stl" />
        <mesh name="palm_collision_79" file="meshes/arm_and_hand_meshes/collision/decomposed/palm/palmShape_IndexedFaceSet_079.stl" />
        <mesh name="palm_collision_80" file="meshes/arm_and_hand_meshes/collision/decomposed/palm/palmShape_IndexedFaceSet_080.stl" />
        <mesh name="palm_collision_81" file="meshes/arm_and_hand_meshes/collision/decomposed/palm/palmShape_IndexedFaceSet_081.stl" />
        <mesh name="palm_collision_82" file="meshes/arm_and_hand_meshes/collision/decomposed/palm/palmShape_IndexedFaceSet_082.stl" />
        <mesh name="palm_collision_83" file="meshes/arm_and_hand_meshes/collision/decomposed/palm/palmShape_IndexedFaceSet_083.stl" />
        <mesh name="palm_collision_84" file="meshes/arm_and_hand_meshes/collision/decomposed/palm/palmShape_IndexedFaceSet_084.stl" />
        <mesh name="palm_collision_85" file="meshes/arm_and_hand_meshes/collision/decomposed/palm/palmShape_IndexedFaceSet_085.stl" />
        <mesh name="palm_collision_86" file="meshes/arm_and_hand_meshes/collision/decomposed/palm/palmShape_IndexedFaceSet_086.stl" />
        <mesh name="palm_collision_87" file="meshes/arm_and_hand_meshes/collision/decomposed/palm/palmShape_IndexedFaceSet_087.stl" />
        <mesh name="palm_collision_88" file="meshes/arm_and_hand_meshes/collision/decomposed/palm/palmShape_IndexedFaceSet_088.stl" />
        <mesh name="palm_collision_89" file="meshes/arm_and_hand_meshes/collision/decomposed/palm/palmShape_IndexedFaceSet_089.stl" />
        <mesh name="palm_collision_90" file="meshes/arm_and_hand_meshes/collision/decomposed/palm/palmShape_IndexedFaceSet_090.stl" />
        <mesh name="palm_collision_91" file="meshes/arm_and_hand_meshes/collision/decomposed/palm/palmShape_IndexedFaceSet_091.stl" />
        <mesh name="palm_collision_92" file="meshes/arm_and_hand_meshes/collision/decomposed/palm/palmShape_IndexedFaceSet_092.stl" />
        <mesh name="palm_collision_93" file="meshes/arm_and_hand_meshes/collision/decomposed/palm/palmShape_IndexedFaceSet_093.stl" />
        <mesh name="palm_collision_94" file="meshes/arm_and_hand_meshes/collision/decomposed/palm/palmShape_IndexedFaceSet_094.stl" />
        <mesh name="palm_collision_95" file="meshes/arm_and_hand_meshes/collision/decomposed/palm/palmShape_IndexedFaceSet_095.stl" />
        <mesh name="palm_collision_96" file="meshes/arm_and_hand_meshes/collision/decomposed/palm/palmShape_IndexedFaceSet_096.stl" />
        <mesh name="palm_collision_97" file="meshes/arm_and_hand_meshes/collision/decomposed/palm/palmShape_IndexedFaceSet_097.stl" />
        <mesh name="palm_collision_98" file="meshes/arm_and_hand_meshes/collision/decomposed/palm/palmShape_IndexedFaceSet_098.stl" />
        <mesh name="palm_collision_99" file="meshes/arm_and_hand_meshes/collision/decomposed/palm/palmShape_IndexedFaceSet_099.stl" />
        <mesh name="palm_collision_100" file="meshes/arm_and_hand_meshes/collision/decomposed/palm/palmShape_IndexedFaceSet_100.stl" />
        <mesh name="palm_collision_101" file="meshes/arm_and_hand_meshes/collision/decomposed/palm/palmShape_IndexedFaceSet_101.stl" />
        <mesh name="palm_collision_102" file="meshes/arm_and_hand_meshes/collision/decomposed/palm/palmShape_IndexedFaceSet_102.stl" />
        <mesh name="palm_collision_103" file="meshes/arm_and_hand_meshes/collision/decomposed/palm/palmShape_IndexedFaceSet_103.stl" />
        <mesh name="palm_collision_104" file="meshes/arm_and_hand_meshes/collision/decomposed/palm/palmShape_IndexedFaceSet_104.stl" />
        <mesh name="palm_collision_105" file="meshes/arm_and_hand_meshes/collision/decomposed/palm/palmShape_IndexedFaceSet_105.stl" />
        <mesh name="palm_collision_106" file="meshes/arm_and_hand_meshes/collision/decomposed/palm/palmShape_IndexedFaceSet_106.stl" />
        <mesh name="palm_collision_107" file="meshes/arm_and_hand_meshes/collision/decomposed/palm/palmShape_IndexedFaceSet_107.stl" />
        <mesh name="palm_collision_108" file="meshes/arm_and_hand_meshes/collision/decomposed/palm/palmShape_IndexedFaceSet_108.stl" />
        <mesh name="palm_collision_109" file="meshes/arm_and_hand_meshes/collision/decomposed/palm/palmShape_IndexedFaceSet_109.stl" />
        <mesh name="palm_collision_110" file="meshes/arm_and_hand_meshes/collision/decomposed/palm/palmShape_IndexedFaceSet_110.stl" />
        <mesh name="palm_collision_111" file="meshes/arm_and_hand_meshes/collision/decomposed/palm/palmShape_IndexedFaceSet_111.stl" />
        <mesh name="palm_collision_112" file="meshes/arm_and_hand_meshes/collision/decomposed/palm/palmShape_IndexedFaceSet_112.stl" />
        <mesh name="palm_collision_113" file="meshes/arm_and_hand_meshes/collision/decomposed/palm/palmShape_IndexedFaceSet_113.stl" />
        <mesh name="palm_collision_114" file="meshes/arm_and_hand_meshes/collision/decomposed/palm/palmShape_IndexedFaceSet_114.stl" />
        <mesh name="palm_collision_115" file="meshes/arm_and_hand_meshes/collision/decomposed/palm/palmShape_IndexedFaceSet_115.stl" />
        <mesh name="palm_collision_116" file="meshes/arm_and_hand_meshes/collision/decomposed/palm/palmShape_IndexedFaceSet_116.stl" />
        <mesh name="palm_collision_117" file="meshes/arm_and_hand_meshes/collision/decomposed/palm/palmShape_IndexedFaceSet_117.stl" />
        <mesh name="palm_collision_118" file="meshes/arm_and_hand_meshes/collision/decomposed/palm/palmShape_IndexedFaceSet_118.stl" />
        <mesh name="palm_collision_119" file="meshes/arm_and_hand_meshes/collision/decomposed/palm/palmShape_IndexedFaceSet_119.stl" />
        <mesh name="palm_collision_120" file="meshes/arm_and_hand_meshes/collision/decomposed/palm/palmShape_IndexedFaceSet_120.stl" />
        <mesh name="palm_collision_121" file="meshes/arm_and_hand_meshes/collision/decomposed/palm/palmShape_IndexedFaceSet_121.stl" />
        <mesh name="palm_collision_122" file="meshes/arm_and_hand_meshes/collision/decomposed/palm/palmShape_IndexedFaceSet_122.stl" />
        <mesh name="palm_collision_123" file="meshes/arm_and_hand_meshes/collision/decomposed/palm/palmShape_IndexedFaceSet_123.stl" />
        <mesh name="palm_collision_124" file="meshes/arm_and_hand_meshes/collision/decomposed/palm/palmShape_IndexedFaceSet_124.stl" />
        <mesh name="palm_collision_125" file="meshes/arm_and_hand_meshes/collision/decomposed/palm/palmShape_IndexedFaceSet_125.stl" />
        <mesh name="palm_collision_126" file="meshes/arm_and_hand_meshes/collision/decomposed/palm/palmShape_IndexedFaceSet_126.stl" />
        <mesh name="palm_collision_127" file="meshes/arm_and_hand_meshes/collision/decomposed/palm/palmShape_IndexedFaceSet_127.stl" />
        <mesh name="palm_collision_128" file="meshes/arm_and_hand_meshes/collision/decomposed/palm/palmShape_IndexedFaceSet_128.stl" />
        <mesh name="palm_collision_129" file="meshes/arm_and_hand_meshes/collision/decomposed/palm/palmShape_IndexedFaceSet_129.stl" />
        <mesh name="palm_collision_130" file="meshes/arm_and_hand_meshes/collision/decomposed/palm/palmShape_IndexedFaceSet_130.stl" />
        <mesh name="palm_collision_131" file="meshes/arm_and_hand_meshes/collision/decomposed/palm/palmShape_IndexedFaceSet_131.stl" />
        <mesh name="palm_collision_132" file="meshes/arm_and_hand_meshes/collision/decomposed/palm/palmShape_IndexedFaceSet_132.stl" />
        <mesh name="palm_collision_133" file="meshes/arm_and_hand_meshes/collision/decomposed/palm/palmShape_IndexedFaceSet_133.stl" />
        <mesh name="palm_collision_134" file="meshes/arm_and_hand_meshes/collision/decomposed/palm/palmShape_IndexedFaceSet_134.stl" />
        <mesh name="palm_collision_135" file="meshes/arm_and_hand_meshes/collision/decomposed/palm/palmShape_IndexedFaceSet_135.stl" />
        <mesh name="palm_collision_136" file="meshes/arm_and_hand_meshes/collision/decomposed/palm/palmShape_IndexedFaceSet_136.stl" />
        <mesh name="palm_collision_137" file="meshes/arm_and_hand_meshes/collision/decomposed/palm/palmff_hinge.stl" />
        <mesh name="palm_collision_138" file="meshes/arm_and_hand_meshes/collision/decomposed/palm/palmlf_palm.stl" />
        <mesh name="palm_collision_139" file="meshes/arm_and_hand_meshes/collision/decomposed/palm/palmlf_palm_top.stl" />
        <mesh name="palm_collision_140" file="meshes/arm_and_hand_meshes/collision/decomposed/palm/palmmf_hinge.stl" />
        <mesh name="palm_collision_141" file="meshes/arm_and_hand_meshes/collision/decomposed/palm/palmrf_hinge.stl" />
        <mesh name="palm_collision_142" file="meshes/arm_and_hand_meshes/collision/decomposed/palm/palmrf_palm.stl" />
        <mesh name="palm_collision_143" file="meshes/arm_and_hand_meshes/collision/decomposed/palm/palmwrist_hinge_right.stl" />
        <mesh name="palm_collision_144" file="meshes/arm_and_hand_meshes/collision/decomposed/palm/palmwrist_hinge_right_small.stl" />
        <mesh name="wrist_visual" file="meshes/arm_and_hand_meshes/visual/wrist.stl" />
        <mesh name="wrist_collision_1" file="meshes/arm_and_hand_meshes/collision/decomposed/wrist/wrist_1.stl" />
        <mesh name="wrist_collision_2" file="meshes/arm_and_hand_meshes/collision/decomposed/wrist/wrist_2.stl" />
        <mesh name="wrist_collision_3" file="meshes/arm_and_hand_meshes/collision/decomposed/wrist/wrist_3.stl" />
        <mesh name="wrist_collision_4" file="meshes/arm_and_hand_meshes/collision/decomposed/wrist/wrist_4.stl" />
        <mesh name="wrist_collision_5" file="meshes/arm_and_hand_meshes/collision/decomposed/wrist/wrist_5.stl" />
        <mesh name="wrist_collision_6" file="meshes/arm_and_hand_meshes/collision/decomposed/wrist/wrist_6.stl" />
        <mesh name="wrist_collision_7" file="meshes/arm_and_hand_meshes/collision/decomposed/wrist/wrist_7.stl" />
        <mesh name="lfmetacarpal_visual" file="meshes/arm_and_hand_meshes/visual/lfmetacarpal.stl" />
        <mesh name="lfmetacarpal_collision_0" file="meshes/arm_and_hand_meshes/collision/decomposed/lfmetacarpal/lfmetacarpalShape_IndexedFaceSet.stl" />
        <mesh name="lfmetacarpal_collision_1" file="meshes/arm_and_hand_meshes/collision/decomposed/lfmetacarpal/lfmetacarpalShape_IndexedFaceSet_001.stl" />
        <mesh name="lfmetacarpal_collision_2" file="meshes/arm_and_hand_meshes/collision/decomposed/lfmetacarpal/lfmetacarpalShape_IndexedFaceSet_002.stl" />
        <mesh name="lfmetacarpal_collision_3" file="meshes/arm_and_hand_meshes/collision/decomposed/lfmetacarpal/lfmetacarpalShape_IndexedFaceSet_003.stl" />
        <mesh name="lfmetacarpal_collision_4" file="meshes/arm_and_hand_meshes/collision/decomposed/lfmetacarpal/lfmetacarpalShape_IndexedFaceSet_004.stl" />
        <mesh name="lfmetacarpal_collision_5" file="meshes/arm_and_hand_meshes/collision/decomposed/lfmetacarpal/lfmetacarpalShape_IndexedFaceSet_005.stl" />
        <mesh name="lfmetacarpal_collision_6" file="meshes/arm_and_hand_meshes/collision/decomposed/lfmetacarpal/lfmetacarpalShape_IndexedFaceSet_006.stl" />
        <mesh name="lfmetacarpal_collision_7" file="meshes/arm_and_hand_meshes/collision/decomposed/lfmetacarpal/lfmetacarpalShape_IndexedFaceSet_007.stl" />
        <mesh name="lfmetacarpal_collision_8" file="meshes/arm_and_hand_meshes/collision/decomposed/lfmetacarpal/lfmetacarpalShape_IndexedFaceSet_008.stl" />
        <mesh name="lfmetacarpal_collision_9" file="meshes/arm_and_hand_meshes/collision/decomposed/lfmetacarpal/lfmetacarpalShape_IndexedFaceSet_009.stl" />
        <mesh name="lfmetacarpal_collision_10" file="meshes/arm_and_hand_meshes/collision/decomposed/lfmetacarpal/lfmetacarpalShape_IndexedFaceSet_010.stl" />
        <mesh name="lfmetacarpal_collision_11" file="meshes/arm_and_hand_meshes/collision/decomposed/lfmetacarpal/lfmetacarpalShape_IndexedFaceSet_011.stl" />
        <mesh name="lfmetacarpal_collision_12" file="meshes/arm_and_hand_meshes/collision/decomposed/lfmetacarpal/lfmetacarpalShape_IndexedFaceSet_012.stl" />
        <mesh name="lfmetacarpal_collision_13" file="meshes/arm_and_hand_meshes/collision/decomposed/lfmetacarpal/lfmetacarpalmetacarpal_001.stl" />
        <mesh name="lfmetacarpal_collision_14" file="meshes/arm_and_hand_meshes/collision/decomposed/lfmetacarpal/lfmetacarpalmetacarpal_002.stl" />
        <mesh name="lfmetacarpal_collision_15" file="meshes/arm_and_hand_meshes/collision/decomposed/lfmetacarpal/lfmetacarpalmetacarpal_003.stl" />
    </asset>
    <worldbody>
        <geom name="floor" size="5 5 0.001" type="plane" material="mat_plane" />
        <light name="light0" pos="0 0 4" dir="0 0 -1" directional="true" castshadow="false" ambient="0.2 0.2 0.2" diffuse="0.8 0.8 0.8" />
        <body name="floor" pos="0 0 0">
            <inertial pos="0 0 0" mass="0" diaginertia="0 0 0" />
        </body>
        <body name="ra_base_link" pos="0 0 0">
            <inertial pos="0 0 0" quat="0.5 0.5 -0.5 0.5" mass="4" diaginertia="0.01125 0.00610633 0.00610633" />
            <geom type="mesh" rgba="0.7 0.7 0.7 1" mesh="base" />
            <body name="ra_shoulder_link" pos="0 0 0.1273">
                <inertial pos="0 0 0" mass="7.778" diaginertia="0.0314743 0.0314743 0.0218756" />
                <joint name="ra_shoulder_pan_joint" pos="0 0 0" axis="0 0 1" limited="false" range="-6.28319 6.28319" />
                <geom type="mesh" rgba="0.7 0.7 0.7 1" mesh="shoulder" />
                <body name="ra_upper_arm_link" pos="0 0.220941 0" quat="0.707107 0 0.707107 0">
                    <inertial pos="0 0 0.306" mass="12.93" diaginertia="0.421754 0.421754 0.0363656" />
                    <joint name="ra_shoulder_lift_joint" pos="0 0 0" axis="0 1 0" limited="false" range="-6.28319 6.28319" />
                    <geom type="mesh" rgba="0.7 0.7 0.7 1" mesh="upperarm_bottom_link" />
                    <geom type="mesh" rgba="0.7 0.7 0.7 1" mesh="upperarm_body_link" />
                    <geom type="mesh" rgba="0.7 0.7 0.7 1" mesh="upperarm_top_link" />
                    <body name="ra_forearm_link" pos="0 -0.1719 0.612">
                        <inertial pos="0 0 0.28615" mass="3.87" diaginertia="0.11107 0.11107 0.0108844" />
                        <joint name="ra_elbow_joint" pos="0 0 0" axis="0 1 0" limited="false" range="-3.14159 3.14159" />
                        <geom type="mesh" rgba="0.7 0.7 0.7 1" mesh="forearm_bottom_link" />
                        <geom type="mesh" rgba="0.7 0.7 0.7 1" mesh="forearm_body_link" />
                        <geom type="mesh" rgba="0.7 0.7 0.7 1" mesh="forearm_top_link" />
                        <body name="ra_wrist_1_link" pos="0 0 0.5723" quat="0.707107 0 0.707107 0">
                            <inertial pos="0 0 0" quat="0.5 0.5 -0.5 0.5" mass="1.96" diaginertia="0.0055125 0.00510825 0.00510825" />
                            <joint name="ra_wrist_1_joint" pos="0 0 0" axis="0 1 0" limited="false" range="-6.28319 6.28319" />
                            <geom type="mesh" rgba="0.7 0.7 0.7 1" mesh="wrist1_base" />
                            <geom type="mesh" rgba="0.7 0.7 0.7 1" mesh="wrist1_link" />
                            <body name="ra_wrist_2_link" pos="0 0.1149 0">
                                <inertial pos="0 0 0" quat="0.5 0.5 -0.5 0.5" mass="1.96" diaginertia="0.0055125 0.00510825 0.00510825" />
                                <joint name="ra_wrist_2_joint" pos="0 0 0" axis="0 0 1" limited="false" range="-6.28319 6.28319" />
                                <geom type="mesh" rgba="0.7 0.7 0.7 1" mesh="wrist2_base" />
                                <geom type="mesh" rgba="0.7 0.7 0.7 1" mesh="wrist2_link" />
                                <body name="ra_wrist_3_link" pos="0 0 0.1157">
                                    <inertial pos="0 0 0" quat="0.5 0.5 -0.5 0.5" mass="0.202" diaginertia="0.000568125 0.000526462 0.000526462" />
                                    <joint name="ra_wrist_3_joint" pos="0 0 0" axis="0 1 0" limited="false" range="-6.28319 6.28319" />
                                    <geom type="mesh" rgba="0.7 0.7 0.7 1" mesh="wrist3" />
                                    <body name="ra_ee_link" pos="0 0.0922 0" quat="0.707107 0 0 0.707107">
                                        <inertial pos="-0.01 0 0" mass="0.001" diaginertia="1.66667e-08 1.66667e-08 1.66667e-08" />
                                        <geom size="0.005 0.005 0.005" pos="-0.01 0 0" type="box" />
                                        <body name="rh_forearm" pos="0 0 0">
                                            <inertial pos="0 0 0.09" mass="3" diaginertia="0.0138 0.0138 0.00744" />
                                            <geom class="visual" type="mesh" material="plastic" mesh="forearm_visual" />
                                            <geom class="collision" type="mesh" material="plastic" mesh="forearm_collision" />
                                            <geom class="collision" type="mesh" material="plastic" mesh="forearm_collision_wrist" />
                                            <body name="rh_wrist" pos="0 -0.01 0.213">
                                                <inertial pos="0 0 0.029" quat="0.5 0.5 0.5 0.5" mass="0.1" diaginertia="6.4e-05 4.38e-05 3.5e-05" />
                                                <joint name="rh_WRJ2" pos="0 0 0" axis="0 1 0" range="-0.523599 0.174533" damping="1" />
                                                <geom class="visual" type="mesh" material="metal" mesh="wrist_visual" />
                                                <geom class="collision" type="mesh" material="metal" mesh="wrist_collision_1" />
                                                <geom class="collision" type="mesh" material="metal" mesh="wrist_collision_2" />
                                                <geom class="collision" type="mesh" material="metal" mesh="wrist_collision_3" />
                                                <geom class="collision" type="mesh" material="metal" mesh="wrist_collision_4" />
                                                <geom class="collision" type="mesh" material="metal" mesh="wrist_collision_5" />
                                                <geom class="collision" type="mesh" material="metal" mesh="wrist_collision_6" />
                                                <geom class="collision" type="mesh" material="metal" mesh="wrist_collision_7" />
                                                <body name="rh_palm" pos="0 0 0.034">
                                                    <inertial pos="0 0 0.035" quat="0.707107 0 0 0.707107" mass="0.3" diaginertia="0.0005287 0.0003581 0.000191" />
                                                    <joint name="rh_WRJ1" pos="0 0 0" axis="1 0 0" range="-0.698132 0.488692" damping="1" />
                                                    <geom class="visual" type="mesh" material="plastic" mesh="palm_visual" />
                                                    <geom class="collision" type="mesh" material="plastic" mesh="palm_collision_0" />
                                                    <geom class="collision" type="mesh" material="plastic" mesh="palm_collision_1" />
                                                    <geom class="collision" type="mesh" material="plastic" mesh="palm_collision_2" />
                                                    <geom class="collision" type="mesh" material="plastic" mesh="palm_collision_3" />
                                                    <geom class="collision" type="mesh" material="plastic" mesh="palm_collision_4" />
                                                    <geom class="collision" type="mesh" material="plastic" mesh="palm_collision_5" />
                                                    <geom class="collision" type="mesh" material="plastic" mesh="palm_collision_6" />
                                                    <geom class="collision" type="mesh" material="plastic" mesh="palm_collision_7" />
                                                    <geom class="collision" type="mesh" material="plastic" mesh="palm_collision_8" />
                                                    <geom class="collision" type="mesh" material="plastic" mesh="palm_collision_9" />
                                                    <geom class="collision" type="mesh" material="plastic" mesh="palm_collision_10" />
                                                    <geom class="collision" type="mesh" material="plastic" mesh="palm_collision_11" />
                                                    <geom class="collision" type="mesh" material="plastic" mesh="palm_collision_12" />
                                                    <geom class="collision" type="mesh" material="plastic" mesh="palm_collision_13" />
                                                    <geom class="collision" type="mesh" material="plastic" mesh="palm_collision_14" />
                                                    <geom class="collision" type="mesh" material="plastic" mesh="palm_collision_15" />
                                                    <geom class="collision" type="mesh" material="plastic" mesh="palm_collision_16" />
                                                    <geom class="collision" type="mesh" material="plastic" mesh="palm_collision_17" />
                                                    <geom class="collision" type="mesh" material="plastic" mesh="palm_collision_18" />
                                                    <geom class="collision" type="mesh" material="plastic" mesh="palm_collision_19" />
                                                    <geom class="collision" type="mesh" material="plastic" mesh="palm_collision_20" />
                                                    <geom class="collision" type="mesh" material="plastic" mesh="palm_collision_21" />
                                                    <geom class="collision" type="mesh" material="plastic" mesh="palm_collision_22" />
                                                    <geom class="collision" type="mesh" material="plastic" mesh="palm_collision_23" />
                                                    <geom class="collision" type="mesh" material="plastic" mesh="palm_collision_24" />
                                                    <geom class="collision" type="mesh" material="plastic" mesh="palm_collision_25" />
                                                    <geom class="collision" type="mesh" material="plastic" mesh="palm_collision_26" />
                                                    <geom class="collision" type="mesh" material="plastic" mesh="palm_collision_27" />
                                                    <geom class="collision" type="mesh" material="plastic" mesh="palm_collision_28" />
                                                    <geom class="collision" type="mesh" material="plastic" mesh="palm_collision_29" />
                                                    <geom class="collision" type="mesh" material="plastic" mesh="palm_collision_30" />
                                                    <geom class="collision" type="mesh" material="plastic" mesh="palm_collision_31" />
                                                    <geom class="collision" type="mesh" material="plastic" mesh="palm_collision_32" />
                                                    <geom class="collision" type="mesh" material="plastic" mesh="palm_collision_33" />
                                                    <geom class="collision" type="mesh" material="plastic" mesh="palm_collision_34" />
                                                    <geom class="collision" type="mesh" material="plastic" mesh="palm_collision_35" />
                                                    <geom class="collision" type="mesh" material="plastic" mesh="palm_collision_36" />
                                                    <geom class="collision" type="mesh" material="plastic" mesh="palm_collision_37" />
                                                    <geom class="collision" type="mesh" material="plastic" mesh="palm_collision_38" />
                                                    <geom class="collision" type="mesh" material="plastic" mesh="palm_collision_39" />
                                                    <geom class="collision" type="mesh" material="plastic" mesh="palm_collision_40" />
                                                    <geom class="collision" type="mesh" material="plastic" mesh="palm_collision_41" />
                                                    <geom class="collision" type="mesh" material="plastic" mesh="palm_collision_42" />
                                                    <geom class="collision" type="mesh" material="plastic" mesh="palm_collision_43" />
                                                    <geom class="collision" type="mesh" material="plastic" mesh="palm_collision_44" />
                                                    <geom class="collision" type="mesh" material="plastic" mesh="palm_collision_45" />
                                                    <geom class="collision" type="mesh" material="plastic" mesh="palm_collision_46" />
                                                    <geom class="collision" type="mesh" material="plastic" mesh="palm_collision_47" />
                                                    <geom class="collision" type="mesh" material="plastic" mesh="palm_collision_48" />
                                                    <geom class="collision" type="mesh" material="plastic" mesh="palm_collision_49" />
                                                    <geom class="collision" type="mesh" material="plastic" mesh="palm_collision_50" />
                                                    <geom class="collision" type="mesh" material="plastic" mesh="palm_collision_51" />
                                                    <geom class="collision" type="mesh" material="plastic" mesh="palm_collision_52" />
                                                    <geom class="collision" type="mesh" material="plastic" mesh="palm_collision_53" />
                                                    <geom class="collision" type="mesh" material="plastic" mesh="palm_collision_54" />
                                                    <geom class="collision" type="mesh" material="plastic" mesh="palm_collision_55" />
                                                    <geom class="collision" type="mesh" material="plastic" mesh="palm_collision_56" />
                                                    <geom class="collision" type="mesh" material="plastic" mesh="palm_collision_57" />
                                                    <geom class="collision" type="mesh" material="plastic" mesh="palm_collision_58" />
                                                    <geom class="collision" type="mesh" material="plastic" mesh="palm_collision_59" />
                                                    <geom class="collision" type="mesh" material="plastic" mesh="palm_collision_60" />
                                                    <geom class="collision" type="mesh" material="plastic" mesh="palm_collision_61" />
                                                    <geom class="collision" type="mesh" material="plastic" mesh="palm_collision_62" />
                                                    <geom class="collision" type="mesh" material="plastic" mesh="palm_collision_63" />
                                                    <geom class="collision" type="mesh" material="plastic" mesh="palm_collision_64" />
                                                    <geom class="collision" type="mesh" material="plastic" mesh="palm_collision_65" />
                                                    <geom class="collision" type="mesh" material="plastic" mesh="palm_collision_66" />
                                                    <geom class="collision" type="mesh" material="plastic" mesh="palm_collision_67" />
                                                    <geom class="collision" type="mesh" material="plastic" mesh="palm_collision_68" />
                                                    <geom class="collision" type="mesh" material="plastic" mesh="palm_collision_69" />
                                                    <geom class="collision" type="mesh" material="plastic" mesh="palm_collision_70" />
                                                    <geom class="collision" type="mesh" material="plastic" mesh="palm_collision_71" />
                                                    <geom class="collision" type="mesh" material="plastic" mesh="palm_collision_72" />
                                                    <geom class="collision" type="mesh" material="plastic" mesh="palm_collision_73" />
                                                    <geom class="collision" type="mesh" material="plastic" mesh="palm_collision_74" />
                                                    <geom class="collision" type="mesh" material="plastic" mesh="palm_collision_75" />
                                                    <geom class="collision" type="mesh" material="plastic" mesh="palm_collision_76" />
                                                    <geom class="collision" type="mesh" material="plastic" mesh="palm_collision_77" />
                                                    <geom class="collision" type="mesh" material="plastic" mesh="palm_collision_78" />
                                                    <geom class="collision" type="mesh" material="plastic" mesh="palm_collision_79" />
                                                    <geom class="collision" type="mesh" material="plastic" mesh="palm_collision_80" />
                                                    <geom class="collision" type="mesh" material="plastic" mesh="palm_collision_81" />
                                                    <geom class="collision" type="mesh" material="plastic" mesh="palm_collision_82" />
                                                    <geom class="collision" type="mesh" material="plastic" mesh="palm_collision_83" />
                                                    <geom class="collision" type="mesh" material="plastic" mesh="palm_collision_84" />
                                                    <geom class="collision" type="mesh" material="plastic" mesh="palm_collision_85" />
                                                    <geom class="collision" type="mesh" material="plastic" mesh="palm_collision_86" />
                                                    <geom class="collision" type="mesh" material="plastic" mesh="palm_collision_87" />
                                                    <geom class="collision" type="mesh" material="plastic" mesh="palm_collision_88" />
                                                    <geom class="collision" type="mesh" material="plastic" mesh="palm_collision_89" />
                                                    <geom class="collision" type="mesh" material="plastic" mesh="palm_collision_90" />
                                                    <geom class="collision" type="mesh" material="plastic" mesh="palm_collision_91" />
                                                    <geom class="collision" type="mesh" material="plastic" mesh="palm_collision_92" />
                                                    <geom class="collision" type="mesh" material="plastic" mesh="palm_collision_93" />
                                                    <geom class="collision" type="mesh" material="plastic" mesh="palm_collision_94" />
                                                    <geom class="collision" type="mesh" material="plastic" mesh="palm_collision_95" />
                                                    <geom class="collision" type="mesh" material="plastic" mesh="palm_collision_96" />
                                                    <geom class="collision" type="mesh" material="plastic" mesh="palm_collision_97" />
                                                    <geom class="collision" type="mesh" material="plastic" mesh="palm_collision_98" />
                                                    <geom class="collision" type="mesh" material="plastic" mesh="palm_collision_99" />
                                                    <geom class="collision" type="mesh" material="plastic" mesh="palm_collision_100" />
                                                    <geom class="collision" type="mesh" material="plastic" mesh="palm_collision_101" />
                                                    <geom class="collision" type="mesh" material="plastic" mesh="palm_collision_102" />
                                                    <geom class="collision" type="mesh" material="plastic" mesh="palm_collision_103" />
                                                    <geom class="collision" type="mesh" material="plastic" mesh="palm_collision_104" />
                                                    <geom class="collision" type="mesh" material="plastic" mesh="palm_collision_105" />
                                                    <geom class="collision" type="mesh" material="plastic" mesh="palm_collision_106" />
                                                    <geom class="collision" type="mesh" material="plastic" mesh="palm_collision_107" />
                                                    <geom class="collision" type="mesh" material="plastic" mesh="palm_collision_108" />
                                                    <geom class="collision" type="mesh" material="plastic" mesh="palm_collision_109" />
                                                    <geom class="collision" type="mesh" material="plastic" mesh="palm_collision_110" />
                                                    <geom class="collision" type="mesh" material="plastic" mesh="palm_collision_111" />
                                                    <geom class="collision" type="mesh" material="plastic" mesh="palm_collision_112" />
                                                    <geom class="collision" type="mesh" material="plastic" mesh="palm_collision_113" />
                                                    <geom class="collision" type="mesh" material="plastic" mesh="palm_collision_114" />
                                                    <geom class="collision" type="mesh" material="plastic" mesh="palm_collision_115" />
                                                    <geom class="collision" type="mesh" material="plastic" mesh="palm_collision_116" />
                                                    <geom class="collision" type="mesh" material="plastic" mesh="palm_collision_117" />
                                                    <geom class="collision" type="mesh" material="plastic" mesh="palm_collision_118" />
                                                    <geom class="collision" type="mesh" material="plastic" mesh="palm_collision_119" />
                                                    <geom class="collision" type="mesh" material="plastic" mesh="palm_collision_120" />
                                                    <geom class="collision" type="mesh" material="plastic" mesh="palm_collision_121" />
                                                    <geom class="collision" type="mesh" material="plastic" mesh="palm_collision_122" />
                                                    <geom class="collision" type="mesh" material="plastic" mesh="palm_collision_123" />
                                                    <geom class="collision" type="mesh" material="plastic" mesh="palm_collision_124" />
                                                    <geom class="collision" type="mesh" material="plastic" mesh="palm_collision_125" />
                                                    <geom class="collision" type="mesh" material="plastic" mesh="palm_collision_126" />
                                                    <geom class="collision" type="mesh" material="plastic" mesh="palm_collision_127" />
                                                    <geom class="collision" type="mesh" material="plastic" mesh="palm_collision_128" />
                                                    <geom class="collision" type="mesh" material="plastic" mesh="palm_collision_129" />
                                                    <geom class="collision" type="mesh" material="plastic" mesh="palm_collision_130" />
                                                    <geom class="collision" type="mesh" material="plastic" mesh="palm_collision_131" />
                                                    <geom class="collision" type="mesh" material="plastic" mesh="palm_collision_132" />
                                                    <geom class="collision" type="mesh" material="plastic" mesh="palm_collision_133" />
                                                    <geom class="collision" type="mesh" material="plastic" mesh="palm_collision_134" />
                                                    <geom class="collision" type="mesh" material="plastic" mesh="palm_collision_135" />
                                                    <geom class="collision" type="mesh" material="plastic" mesh="palm_collision_136" />
                                                    <geom class="collision" type="mesh" material="plastic" mesh="palm_collision_137" />
                                                    <geom class="collision" type="mesh" material="plastic" mesh="palm_collision_138" />
                                                    <geom class="collision" type="mesh" material="plastic" mesh="palm_collision_139" />
                                                    <geom class="collision" type="mesh" material="plastic" mesh="palm_collision_140" />
                                                    <geom class="collision" type="mesh" material="plastic" mesh="palm_collision_141" />
                                                    <geom class="collision" type="mesh" material="plastic" mesh="palm_collision_142" />
                                                    <geom class="collision" type="mesh" material="plastic" mesh="palm_collision_143" />
                                                    <geom class="collision" type="mesh" material="plastic" mesh="palm_collision_144" />
                                                    <body name="rh_manipulator" pos="0 0 0.05">
                                                        <inertial pos="0 0 0.05" mass="0" diaginertia="0 0 0" />
                                                    </body>
                                                    <body name="rh_imu" pos="0.01785 0.00765 0.049125" quat="2.31079e-07 -2.31079e-07 0.707107 0.707107">
                                                        <inertial pos="0.01785 0.00765 0.049125" quat="2.31079e-07 -2.31079e-07 0.707107 0.707107" mass="0" diaginertia="0 0 0" />
                                                    </body>
                                                    <body name="rh_ffknuckle" pos="0.033 0 0.095">
                                                        <inertial pos="0 0 0" quat="0.5 0.5 -0.5 0.5" mass="0.008" diaginertia="3.2e-07 2.6e-07 2.6e-07" />
                                                        <joint name="rh_FFJ4" class="FJ4" pos="0 0 0" axis="0 -1 0" />
                                                        <geom class="visual" type="mesh" material="metal" mesh="knuckle_visual" />
                                                        <geom class="collision" type="mesh" material="metal" mesh="knuckle_collision" />
                                                        <body name="rh_ffproximal" pos="0 0 0">
                                                            <inertial pos="0 0 0.0225" quat="0.707107 0 0 0.707107" mass="0.03" diaginertia="1e-05 9.8e-06 1.8e-06" />
                                                            <joint name="rh_FFJ3" class="FJ3" pos="0 0 0" axis="1 0 0" />
                                                            <geom class="visual" type="mesh" material="plastic" mesh="F3_visual" />
                                                            <geom class="collision" type="mesh" material="plastic" mesh="F3_collision_proximal" />
                                                            <geom class="collision" type="mesh" material="plastic" mesh="F3_collision_distal" />
                                                            <body name="rh_ffmiddle" pos="0 0 0.045">
                                                                <inertial pos="0 0 0.0125" quat="0.707107 0 0 0.707107" mass="0.017" diaginertia="2.7e-06 2.6e-06 8.7e-07" />
                                                                <joint name="rh_FFJ2" class="FJ2" pos="0 0 0" axis="1 0 0" />
                                                                <geom class="visual" type="mesh" material="plastic" mesh="F2_visual" />
                                                                <geom class="collision" type="mesh" material="plastic" mesh="F2_collision_proximal" />
                                                                <geom class="collision" type="mesh" material="plastic" mesh="F2_collision_middle" />
                                                                <geom class="collision" type="mesh" material="plastic" mesh="F2_collision_distal" />
                                                                <body name="rh_ffdistal" pos="0 0 0.025">
                                                                    <inertial pos="0 0 0.012" quat="0.707107 0 0 0.707107" mass="0.012" diaginertia="1.1e-06 9.4e-07 5.3e-07" />
                                                                    <joint name="rh_FFJ1" class="FJ1" pos="0 0 0" axis="1 0 0" />
                                                                    <geom class="visual" type="mesh" material="plastic" mesh="F1_visual" />
                                                                    <geom class="collision" type="mesh" material="plastic" mesh="F1_collision" />
                                                                    <body name="rh_fftip" pos="0 0 0.026">
                                                                        <inertial pos="0 0 0" mass="0.001" diaginertia="0 0 0" />
                                                                    </body>
                                                                </body>
                                                            </body>
                                                        </body>
                                                    </body>
                                                    <body name="rh_mfknuckle" pos="0.011 0 0.099">
                                                        <inertial pos="0 0 0" quat="0.5 0.5 -0.5 0.5" mass="0.008" diaginertia="3.2e-07 2.6e-07 2.6e-07" />
                                                        <joint name="rh_MFJ4" class="FJ4" pos="0 0 0" axis="0 -1 0" />
                                                        <geom class="visual" type="mesh" material="metal" mesh="knuckle_visual" />
                                                        <geom class="collision" type="mesh" material="metal" mesh="knuckle_collision" />
                                                        <body name="rh_mfproximal" pos="0 0 0">
                                                            <inertial pos="0 0 0.0225" quat="0.707107 0 0 0.707107" mass="0.03" diaginertia="1e-05 9.8e-06 1.8e-06" />
                                                            <joint name="rh_MFJ3" class="FJ3" pos="0 0 0" axis="1 0 0" />
                                                            <geom class="visual" type="mesh" material="plastic" mesh="F3_visual" />
                                                            <geom class="collision" type="mesh" material="plastic" mesh="F3_collision_proximal" />
                                                            <geom class="collision" type="mesh" material="plastic" mesh="F3_collision_distal" />
                                                            <body name="rh_mfmiddle" pos="0 0 0.045">
                                                                <inertial pos="0 0 0.0125" quat="0.707107 0 0 0.707107" mass="0.017" diaginertia="2.7e-06 2.6e-06 8.7e-07" />
                                                                <joint name="rh_MFJ2" class="FJ2" pos="0 0 0" axis="1 0 0" />
                                                                <geom class="visual" type="mesh" material="plastic" mesh="F2_visual" />
                                                                <geom class="collision" type="mesh" material="plastic" mesh="F2_collision_proximal" />
                                                                <geom class="collision" type="mesh" material="plastic" mesh="F2_collision_middle" />
                                                                <geom class="collision" type="mesh" material="plastic" mesh="F2_collision_distal" />
                                                                <body name="rh_mfdistal" pos="0 0 0.025">
                                                                    <inertial pos="0 0 0.012" quat="0.707107 0 0 0.707107" mass="0.012" diaginertia="1.1e-06 9.4e-07 5.3e-07" />
                                                                    <joint name="rh_MFJ1" class="FJ1" pos="0 0 0" axis="1 0 0" />
                                                                    <geom class="visual" type="mesh" material="plastic" mesh="F1_visual" />
                                                                    <geom class="collision" type="mesh" material="plastic" mesh="F1_collision" />
                                                                    <body name="rh_mftip" pos="0 0 0.026">
                                                                        <inertial pos="0 0 0" mass="0.001" diaginertia="0 0 0" />
                                                                    </body>
                                                                </body>
                                                            </body>
                                                        </body>
                                                    </body>
                                                    <body name="rh_rfknuckle" pos="-0.011 0 0.095">
                                                        <inertial pos="0 0 0" quat="0.5 0.5 -0.5 0.5" mass="0.008" diaginertia="3.2e-07 2.6e-07 2.6e-07" />
                                                        <joint name="rh_RFJ4" class="FJ4" pos="0 0 0" axis="0 1 0" />
                                                        <geom class="visual" type="mesh" material="metal" mesh="knuckle_visual" />
                                                        <geom class="collision" type="mesh" material="metal" mesh="knuckle_collision" />
                                                        <body name="rh_rfproximal" pos="0 0 0">
                                                            <inertial pos="0 0 0.0225" quat="0.707107 0 0 0.707107" mass="0.03" diaginertia="1e-05 9.8e-06 1.8e-06" />
                                                            <joint name="rh_RFJ3" class="FJ3" pos="0 0 0" axis="1 0 0" />
                                                            <geom class="visual" type="mesh" material="plastic" mesh="F3_visual" />
                                                            <geom class="collision" type="mesh" material="plastic" mesh="F3_collision_proximal" />
                                                            <geom class="collision" type="mesh" material="plastic" mesh="F3_collision_distal" />
                                                            <body name="rh_rfmiddle" pos="0 0 0.045">
                                                                <inertial pos="0 0 0.0125" quat="0.707107 0 0 0.707107" mass="0.017" diaginertia="2.7e-06 2.6e-06 8.7e-07" />
                                                                <joint name="rh_RFJ2" class="FJ2" pos="0 0 0" axis="1 0 0" />
                                                                <geom class="visual" type="mesh" material="plastic" mesh="F2_visual" />
                                                                <geom class="collision" type="mesh" material="plastic" mesh="F2_collision_proximal" />
                                                                <geom class="collision" type="mesh" material="plastic" mesh="F2_collision_middle" />
                                                                <geom class="collision" type="mesh" material="plastic" mesh="F2_collision_distal" />
                                                                <body name="rh_rfdistal" pos="0 0 0.025">
                                                                    <inertial pos="0 0 0.012" quat="0.707107 0 0 0.707107" mass="0.012" diaginertia="1.1e-06 9.4e-07 5.3e-07" />
                                                                    <joint name="rh_RFJ1" class="FJ1" pos="0 0 0" axis="1 0 0" />
                                                                    <geom class="visual" type="mesh" material="plastic" mesh="F1_visual" />
                                                                    <geom class="collision" type="mesh" material="plastic" mesh="F1_collision" />
                                                                    <body name="rh_rftip" pos="0 0 0.026">
                                                                        <inertial pos="0 0 0" mass="0.001" diaginertia="0 0 0" />
                                                                    </body>
                                                                </body>
                                                            </body>
                                                        </body>
                                                    </body>
                                                    <body name="rh_lfmetacarpal" pos="-0.033 0 0.02071">
                                                        <inertial pos="0 0 0.04" quat="0.707107 0 0 0.707107" mass="0.03" diaginertia="1.638e-05 1.45e-05 4.272e-06" />
                                                        <joint name="rh_LFJ5" pos="0 0 0" axis="0.573576 0 0.819152" range="0 0.785398" />
                                                        <geom class="visual" type="mesh" material="plastic" mesh="lfmetacarpal_visual" />
                                                        <geom class="collision" type="mesh" material="plastic" mesh="lfmetacarpal_collision_0" />
                                                        <geom class="collision" type="mesh" material="plastic" mesh="lfmetacarpal_collision_1" />
                                                        <geom class="collision" type="mesh" material="plastic" mesh="lfmetacarpal_collision_2" />
                                                        <geom class="collision" type="mesh" material="plastic" mesh="lfmetacarpal_collision_3" />
                                                        <geom class="collision" type="mesh" material="plastic" mesh="lfmetacarpal_collision_4" />
                                                        <geom class="collision" type="mesh" material="plastic" mesh="lfmetacarpal_collision_5" />
                                                        <geom class="collision" type="mesh" material="plastic" mesh="lfmetacarpal_collision_6" />
                                                        <geom class="collision" type="mesh" material="plastic" mesh="lfmetacarpal_collision_7" />
                                                        <geom class="collision" type="mesh" material="plastic" mesh="lfmetacarpal_collision_8" />
                                                        <geom class="collision" type="mesh" material="plastic" mesh="lfmetacarpal_collision_9" />
                                                        <geom class="collision" type="mesh" material="plastic" mesh="lfmetacarpal_collision_10" />
                                                        <geom class="collision" type="mesh" material="plastic" mesh="lfmetacarpal_collision_11" />
                                                        <geom class="collision" type="mesh" material="plastic" mesh="lfmetacarpal_collision_12" />
                                                        <geom class="collision" type="mesh" material="plastic" mesh="lfmetacarpal_collision_13" />
                                                        <geom class="collision" type="mesh" material="plastic" mesh="lfmetacarpal_collision_14" />
                                                        <geom class="collision" type="mesh" material="plastic" mesh="lfmetacarpal_collision_15" />
                                                        <body name="rh_lfknuckle" pos="0 0 0.06579">
                                                            <inertial pos="0 0 0" quat="0.5 0.5 -0.5 0.5" mass="0.008" diaginertia="3.2e-07 2.6e-07 2.6e-07" />
                                                            <joint name="rh_LFJ4" class="FJ4" pos="0 0 0" axis="0 1 0" />
                                                            <geom class="visual" type="mesh" material="metal" mesh="knuckle_visual" />
                                                            <geom class="collision" type="mesh" material="metal" mesh="knuckle_collision" />
                                                            <body name="rh_lfproximal" pos="0 0 0">
                                                                <inertial pos="0 0 0.0225" quat="0.707107 0 0 0.707107" mass="0.03" diaginertia="1e-05 9.8e-06 1.8e-06" />
                                                                <joint name="rh_LFJ3" class="FJ3" pos="0 0 0" axis="1 0 0" />
                                                                <geom class="visual" type="mesh" material="plastic" mesh="F3_visual" />
                                                                <geom class="collision" type="mesh" material="plastic" mesh="F3_collision_proximal" />
                                                                <geom class="collision" type="mesh" material="plastic" mesh="F3_collision_distal" />
                                                                <body name="rh_lfmiddle" pos="0 0 0.045">
                                                                    <inertial pos="0 0 0.0125" quat="0.707107 0 0 0.707107" mass="0.017" diaginertia="2.7e-06 2.6e-06 8.7e-07" />
                                                                    <joint name="rh_LFJ2" class="FJ2" pos="0 0 0" axis="1 0 0" />
                                                                    <geom class="visual" type="mesh" material="plastic" mesh="F2_visual" />
                                                                    <geom class="collision" type="mesh" material="plastic" mesh="F2_collision_proximal" />
                                                                    <geom class="collision" type="mesh" material="plastic" mesh="F2_collision_middle" />
                                                                    <geom class="collision" type="mesh" material="plastic" mesh="F2_collision_distal" />
                                                                    <body name="rh_lfdistal" pos="0 0 0.025">
                                                                        <inertial pos="0 0 0.012" quat="0.707107 0 0 0.707107" mass="0.012" diaginertia="1.1e-06 9.4e-07 5.3e-07" />
                                                                        <joint name="rh_LFJ1" class="FJ1" pos="0 0 0" axis="1 0 0" />
                                                                        <geom class="visual" type="mesh" material="plastic" mesh="F1_visual" />
                                                                        <geom class="collision" type="mesh" material="plastic" mesh="F1_collision" />
                                                                        <body name="rh_lftip" pos="0 0 0.026">
                                                                            <inertial pos="0 0 0" mass="0.001" diaginertia="0 0 0" />
                                                                        </body>
                                                                    </body>
                                                                </body>
                                                            </body>
                                                        </body>
                                                    </body>
                                                    <body name="rh_thbase" pos="0.034 -0.0085 0.029" quat="0.92388 0 0.382683 0">
                                                        <inertial pos="0 0 0" mass="0.01" diaginertia="1.6e-07 1.6e-07 1.6e-07" />
                                                        <joint name="rh_THJ5" class="THJ5" pos="0 0 0" axis="0 0 -1" range="-1.0472 1.0472" />
                                                        <body name="rh_thproximal" pos="0 0 0">
                                                            <inertial pos="0 0 0.019" mass="0.04" diaginertia="1.36e-05 1.36e-05 3.13e-06" />
                                                            <joint name="rh_THJ4" class="THJ4" pos="0 0 0" axis="1 0 0" range="0 1.22173" />
                                                            <geom class="visual" type="mesh" material="plastic" mesh="TH3_visual" />
                                                            <geom class="collision" type="mesh" material="plastic" mesh="TH3_collision_proximal" />
                                                            <geom class="collision" type="mesh" material="plastic" mesh="TH3_collision_distal" />
                                                            <body name="rh_thhub" pos="0 0 0.038">
                                                                <inertial pos="0 0 0" mass="0.005" diaginertia="1e-06 1e-06 3e-07" />
                                                                <joint name="rh_THJ3" class="THJ3" pos="0 0 0" axis="1 0 0" range="-0.20944 0.20944" />
                                                                <body name="rh_thmiddle" pos="0 0 0">
                                                                    <inertial pos="0 0 0.016" mass="0.02" diaginertia="5.1e-06 5.1e-06 1.21e-06" />
                                                                    <joint name="rh_THJ2" class="THJ2" pos="0 0 0" axis="0 -1 0" range="-0.698132 0.698132" />
                                                                    <geom class="visual" type="mesh" material="plastic" mesh="TH2_visual" />
                                                                    <geom class="collision" type="mesh" material="plastic" mesh="TH2_collision_proximal" />
                                                                    <geom class="collision" type="mesh" material="plastic" mesh="TH2_collision_middle" />
                                                                    <geom class="collision" type="mesh" material="plastic" mesh="TH2_collision_distal" />
                                                                    <body name="rh_thdistal" pos="0 0 0.032" quat="0.707107 0 0 -0.707107">
                                                                        <inertial pos="0 0 0.01375" quat="0.707107 0 0 0.707107" mass="0.016" diaginertia="2.2e-06 2.1e-06 1e-06" />
                                                                        <joint name="rh_THJ1" class="THJ1" pos="0 0 0" axis="1 0 0" range="0 1.5708" />
                                                                        <geom class="collision" type="mesh" material="plastic" mesh="TH1_collision" />
                                                                        <geom class="visual" type="mesh" material="plastic" mesh="TH1_visual" />
                                                                        <body name="rh_thtip" pos="0 0 0.0275">
                                                                            <inertial pos="0 0 0" mass="0.001" diaginertia="0 0 0" />
                                                                        </body>
                                                                    </body>
                                                                </body>
                                                            </body>
                                                        </body>
                                                    </body>
                                                </body>
                                            </body>
                                        </body>
                                        <body name="ra_tool0" pos="0 0.0922 0" quat="0.707107 -0.707107 0 0">
                                            <inertial pos="0 0.0922 0" quat="0.707107 -0.707107 0 0" mass="0" diaginertia="0 0 0" />
                                        </body>
                                    </body>
                                </body>
                            </body>
                        </body>
                    </body>
                </body>
                <body name="ra_base" pos="0 0 0" quat="1.7949e-09 0 0 -1">
                    <inertial pos="0 0 0" quat="1.7949e-09 0 0 -1" mass="0" diaginertia="0 0 0" />
                </body>
            </body>
        </body>
    </worldbody>
    <contact>
        <exclude body1="rh_forearm" body2="rh_wrist" />
        <exclude body1="rh_wrist" body2="rh_palm" />
        <exclude body1="rh_palm" body2="rh_ffknuckle" />
        <exclude body1="rh_palm" body2="rh_ffproximal" />
        <exclude body1="rh_palm" body2="rh_mfknuckle" />
        <exclude body1="rh_palm" body2="rh_mfproximal" />
        <exclude body1="rh_palm" body2="rh_rfknuckle" />
        <exclude body1="rh_palm" body2="rh_rfproximal" />
        <exclude body1="rh_palm" body2="rh_lfmetacarpal" />
        <exclude body1="rh_palm" body2="rh_thproximal" />
        <exclude body1="rh_ffknuckle" body2="rh_ffproximal" />
        <exclude body1="rh_ffproximal" body2="rh_ffmiddle" />
        <exclude body1="rh_ffmiddle" body2="rh_ffdistal" />
        <exclude body1="rh_mfknuckle" body2="rh_mfproximal" />
        <exclude body1="rh_mfproximal" body2="rh_mfmiddle" />
        <exclude body1="rh_mfmiddle" body2="rh_mfdistal" />
        <exclude body1="rh_rfknuckle" body2="rh_rfproximal" />
        <exclude body1="rh_rfproximal" body2="rh_rfmiddle" />
        <exclude body1="rh_rfmiddle" body2="rh_rfdistal" />
        <exclude body1="rh_lfmetacarpal" body2="rh_lfknuckle" />
        <exclude body1="rh_lfmetacarpal" body2="rh_lfproximal" />
        <exclude body1="rh_lfknuckle" body2="rh_lfproximal" />
        <exclude body1="rh_lfproximal" body2="rh_lfmiddle" />
        <exclude body1="rh_lfmiddle" body2="rh_lfdistal" />
        <exclude body1="rh_thproximal" body2="rh_thmiddle" />
        <exclude body1="rh_thmiddle" body2="rh_thdistal" />
    </contact>
    <tendon>
        <fixed name="rh_FFJ0">
            <joint joint="rh_FFJ1" coef="1" />
            <joint joint="rh_FFJ2" coef="1" />
        </fixed>
        <fixed name="rh_MFJ0">
            <joint joint="rh_MFJ1" coef="1" />
            <joint joint="rh_MFJ2" coef="1" />
        </fixed>
        <fixed name="rh_RFJ0">
            <joint joint="rh_RFJ1" coef="1" />
            <joint joint="rh_RFJ2" coef="1" />
        </fixed>
        <fixed name="rh_LFJ0">
            <joint joint="rh_LFJ1" coef="1" />
            <joint joint="rh_LFJ2" coef="1" />
        </fixed>
    </tendon>
    <actuator>
        <general name="rh_WRJ2" joint="rh_WRJ2" ctrlrange="-0.523599 0.174533" />
        <general name="rh_WRJ1" joint="rh_WRJ1" ctrlrange="-0.698132 0.488692" />
        <general name="rh_FFJ4" joint="rh_FFJ4" ctrlrange="-0.349066 0.349066" />
        <general name="rh_FFJ3" joint="rh_FFJ3" ctrlrange="0 1.5708" />
        <general name="rh_FFJ0" tendon="rh_FFJ0" ctrlrange="0 3.1416" />
        <general name="rh_MFJ4" joint="rh_MFJ4" ctrlrange="-0.349066 0.349066" />
        <general name="rh_MFJ3" joint="rh_MFJ3" ctrlrange="0 1.5708" />
        <general name="rh_MFJ0" tendon="rh_MFJ0" ctrlrange="0 3.1416" />
        <general name="rh_RFJ4" joint="rh_RFJ4" ctrlrange="-0.349066 0.349066" />
        <general name="rh_RFJ3" joint="rh_RFJ3" ctrlrange="0 1.5708" />
        <general name="rh_RFJ0" tendon="rh_RFJ0" ctrlrange="0 3.1416" />
        <general name="rh_LFJ5" joint="rh_LFJ5" ctrlrange="0 0.785398" />
        <general name="rh_LFJ4" joint="rh_LFJ4" ctrlrange="-0.349066 0.349066" />
        <general name="rh_LFJ3" joint="rh_LFJ3" ctrlrange="0 1.5708" />
        <general name="rh_LFJ0" tendon="rh_LFJ0" ctrlrange="0 3.1416" />
        <general name="rh_THJ5" joint="rh_THJ5" ctrlrange="-1.0472 1.0472" />
        <general name="rh_THJ4" joint="rh_THJ4" ctrlrange="0 1.22173" />
        <general name="rh_THJ3" joint="rh_THJ3" ctrlrange="-0.20944 0.20944" />
        <general name="rh_THJ2" joint="rh_THJ2" ctrlrange="-0.698132 0.698132" />
        <general name="rh_THJ1" joint="rh_THJ1" ctrlrange="0 1.5708" />
        <general name="ra_shoulder_pan_joint" joint="ra_shoulder_pan_joint" ctrlrange="-6.28319 6.28319" />
        <general name="ra_shoulder_lift_joint" joint="ra_shoulder_lift_joint" ctrlrange="-6.28319 6.28319" />
        <general name="ra_elbow_joint" joint="ra_elbow_joint" ctrlrange="-3.14159 3.14159" />
        <general name="ra_wrist_1_joint" joint="ra_wrist_1_joint" ctrlrange="-6.28319 6.28319" />
        <general name="ra_wrist_2_joint" joint="ra_wrist_2_joint" ctrlrange="-6.28319 6.28319" />
        <general name="ra_wrist_3_joint" joint="ra_wrist_3_joint" ctrlrange="-6.28319 6.28319" />
    </actuator>
</mujoco>
