<mujoco model="shadowhand_motor">
    <include file="shared_options.xml"></include>
    <asset>
        <include file="shared_assets.xml"></include>
    </asset>
    <worldbody>
        <body name="rh_forearm" pos="0 0 0">
            <inertial pos="0 0 0.09" mass="3" diaginertia="0.0138 0.0138 0.00744" />
            <geom type="mesh" material="plastic" mesh="forearm" contype="2" conaffinity="16777209" />
            <body name="rh_wrist" pos="0 -0.01 0.213">
                <inertial pos="0 0 0.029" quat="0.5 0.5 0.5 0.5" mass="0.1" diaginertia="6.4e-05 4.38e-05 3.5e-05" />
                <joint name="rh_WRJ2" pos="0 0 0" axis="0 1 0" limited="true" range="-0.523599 0.174533" damping="0.5" armature="0.005" margin="0.01" frictionloss="0.001"/>
                <geom type="mesh" material="metal" mesh="wrist" contype="4" conaffinity="16777201" />
                <body name="rh_palm" pos="0 0 0.034">
                    <inertial pos="0 0 0.035" quat="0.707107 0 0 0.707107" mass="0.3" diaginertia="0.0005287 0.0003581 0.000191" />
                    <joint name="rh_WRJ1" pos="0 0 0" axis="1 0 0" limited="true" range="-0.698132 0.488692" damping="0.5" armature="0.005" margin="0.01" frictionloss="0.001"/>
                    <include file="meshes/arm_and_hand_meshes/decomposed/palm/palm_geom.xml" />
                    <body name="rh_manipulator" pos="0 0 0.05">
                        <inertial pos="0 0 0.05" mass="0" diaginertia="0 0 0" />
                    </body>
                    <body name="rh_imu" pos="0.01785 0.00765 0.049125" quat="2.31079e-07 -2.31079e-07 0.707107 0.707107">
                        <inertial pos="0.01785 0.00765 0.049125" quat="2.31079e-07 -2.31079e-07 0.707107 0.707107" mass="0" diaginertia="0 0 0" />
                    </body>
                    <body name="rh_ffknuckle" pos="0.033 0 0.095">
                        <inertial pos="0 0 0" quat="0.5 0.5 -0.5 0.5" mass="0.008" diaginertia="3.2e-07 2.6e-07 2.6e-07" />
                        <joint name="rh_FFJ4" pos="0 0 0" axis="0 -1 0" limited="true" range="-0.349066 0.349066" damping="0.5" armature="0.005" margin="0.01" frictionloss="0.001"/>
                        <geom pos="0 0 0.0005" type="mesh" material="metal" mesh="knuckle" contype="16" conaffinity="16777159" />
                        <body name="rh_ffproximal" pos="0 0 0">
                            <joint name="rh_FFJ3" pos="0 0 0" axis="1 0 0" limited="true" range="0 1.5708" damping="0.5" armature="0.005" margin="0.01" frictionloss="0.001"/>
                            <inertial pos="0 0 0.0225" quat="0.707107 0 0 0.707107" mass="0.03" diaginertia="1e-05 9.8e-06 1.8e-06" />
                            <geom type="mesh" material="plastic" mesh="F3" contype="32" conaffinity="16777095" />
                            <body name="rh_ffmiddle" pos="0 0 0.045">
                                <inertial pos="0 0 0.0125" quat="0.707107 0 0 0.707107" mass="0.017" diaginertia="2.7e-06 2.6e-06 8.7e-07" />
                                <joint name="rh_FFJ2" pos="0 0 0" axis="1 0 0" limited="true" range="0 1.5708" damping="0.5" armature="0.005" margin="0.01" frictionloss="0.001"/>
                                <geom type="mesh" material="plastic" mesh="F2" contype="64" conaffinity="16776991" />
                                <body name="rh_ffdistal" pos="0 0 0.025">
                                    <inertial pos="0 0 0.012" quat="0.707107 0 0 0.707107" mass="0.012" diaginertia="1.1e-06 9.4e-07 5.3e-07" />
                                    <joint name="rh_FFJ1" pos="0 0 0" axis="1 0 0" limited="true" range="0 1.5708" damping="0.5" armature="0.005" margin="0.01" frictionloss="0.001"/>
                                    <geom type="mesh" material="plastic" mesh="F1" contype="128" conaffinity="16777023" />
                                    <body name="rh_fftip" pos="0 0 0.026">
                                        <inertial pos="0 0 0" mass="0.001" diaginertia="0 0 0" />
                                    </body>
                                </body>
                            </body>
                        </body>
                    </body>
                    <body name="rh_mfknuckle" pos="0.011 0 0.099">
                        <inertial pos="0 0 0" quat="0.5 0.5 -0.5 0.5" mass="0.008" diaginertia="3.2e-07 2.6e-07 2.6e-07" />
                        <joint name="rh_MFJ4" pos="0 0 0" axis="0 -1 0" limited="true" range="-0.349066 0.349066" damping="0.5" armature="0.005" margin="0.01" frictionloss="0.001"/>
                        <geom pos="0 0 0.0005" type="mesh" material="metal" mesh="knuckle" contype="256" conaffinity="16776439" />
                        <body name="rh_mfproximal" pos="0 0 0">
                            <joint name="rh_MFJ3" pos="0 0 0" axis="1 0 0" limited="true" range="0 1.5708" damping="0.5" armature="0.005" margin="0.01" frictionloss="0.001"/>
                            <inertial pos="0 0 0.0225" quat="0.707107 0 0 0.707107" mass="0.03" diaginertia="1e-05 9.8e-06 1.8e-06" />
                            <geom type="mesh" material="plastic" mesh="F3" contype="512" conaffinity="16775415" />
                            <body name="rh_mfmiddle" pos="0 0 0.045">
                                <inertial pos="0 0 0.0125" quat="0.707107 0 0 0.707107" mass="0.017" diaginertia="2.7e-06 2.6e-06 8.7e-07" />
                                <joint name="rh_MFJ2" pos="0 0 0" axis="1 0 0" limited="true" range="0 1.5708" damping="0.5" armature="0.005" margin="0.01" frictionloss="0.001"/>
                                <geom type="mesh" material="plastic" mesh="F2" contype="1024" conaffinity="16773631" />
                                <body name="rh_mfdistal" pos="0 0 0.025">
                                    <inertial pos="0 0 0.012" quat="0.707107 0 0 0.707107" mass="0.012" diaginertia="1.1e-06 9.4e-07 5.3e-07" />
                                    <joint name="rh_MFJ1" pos="0 0 0" axis="1 0 0" limited="true" range="0 1.5708" damping="0.5" armature="0.005" margin="0.01" frictionloss="0.001"/>
                                    <geom type="mesh" material="plastic" mesh="F1" contype="2048" conaffinity="16774143" />
                                    <body name="rh_mftip" pos="0 0 0.026">
                                        <inertial pos="0 0 0" mass="0.001" diaginertia="0 0 0" />
                                    </body>
                                </body>
                            </body>
                        </body>
                    </body>
                    <body name="rh_rfknuckle" pos="-0.011 0 0.095">
                        <inertial pos="0 0 0" quat="0.5 0.5 -0.5 0.5" mass="0.008" diaginertia="3.2e-07 2.6e-07 2.6e-07" />
                        <joint name="rh_RFJ4" pos="0 0 0" axis="0 1 0" limited="true" range="-0.349066 0.349066" damping="0.5" armature="0.005" margin="0.01" frictionloss="0.001"/>
                        <geom pos="0 0 0.0005" type="mesh" material="metal" mesh="knuckle" contype="4096" conaffinity="16764919" />
                        <body name="rh_rfproximal" pos="0 0 0">
                            <inertial pos="0 0 0.0225" quat="0.707107 0 0 0.707107" mass="0.03" diaginertia="1e-05 9.8e-06 1.8e-06" />
                            <joint name="rh_RFJ3" pos="0 0 0" axis="1 0 0" limited="true" range="0 1.5708" damping="0.5" armature="0.005" margin="0.01" frictionloss="0.001"/>
                            <geom type="mesh" material="plastic" mesh="F3" contype="8192" conaffinity="16748535" />
                            <body name="rh_rfmiddle" pos="0 0 0.045">
                                <inertial pos="0 0 0.0125" quat="0.707107 0 0 0.707107" mass="0.017" diaginertia="2.7e-06 2.6e-06 8.7e-07" />
                                <joint name="rh_RFJ2" pos="0 0 0" axis="1 0 0" limited="true" range="0 1.5708" damping="0.5" armature="0.005" margin="0.01" frictionloss="0.001"/>
                                <geom type="mesh" material="plastic" mesh="F2" contype="16384" conaffinity="16719871" />
                                <body name="rh_rfdistal" pos="0 0 0.025">
                                    <inertial pos="0 0 0.012" quat="0.707107 0 0 0.707107" mass="0.012" diaginertia="1.1e-06 9.4e-07 5.3e-07" />
                                    <joint name="rh_RFJ1" pos="0 0 0" axis="1 0 0" limited="true" range="0 1.5708" damping="0.5" armature="0.005" margin="0.01" frictionloss="0.001"/>
                                    <geom type="mesh" material="plastic" mesh="F1" contype="32768" conaffinity="16728063" />
                                    <body name="rh_rftip" pos="0 0 0.026">
                                        <inertial pos="0 0 0" mass="0.001" diaginertia="0 0 0" />
                                    </body>
                                </body>
                            </body>
                        </body>
                    </body>
                    <body name="rh_lfmetacarpal" pos="-0.033 0 0.02071">
                        <inertial pos="0 0 0.04" quat="0.707107 0 0 0.707107" mass="0.03" diaginertia="1.638e-05 1.45e-05 4.272e-06" />
                        <joint name="rh_LFJ5" pos="0 0 0" axis="0.573576 0 0.819152" limited="true" range="0 0.785398" damping="0.5" armature="0.005" margin="0.01" frictionloss="0.001"/>
                        <include file="meshes/arm_and_hand_meshes/decomposed/lfmetacarpal/lfmetacarpal_geom.xml" />
                        <body name="rh_lfknuckle" pos="0 0 0.06579">
                            <inertial pos="0 0 0" quat="0.5 0.5 -0.5 0.5" mass="0.008" diaginertia="3.2e-07 2.6e-07 2.6e-07" />
                            <joint name="rh_LFJ4" pos="0 0 0" axis="0 1 0" limited="true" range="-0.349066 0.349066" damping="0.5" armature="0.005" margin="0.01" frictionloss="0.001"/>
                            <geom pos="0 0 0.0005" type="mesh" material="metal" mesh="knuckle" contype="131072" conaffinity="16318463" />
                            <body name="rh_lfproximal" pos="0 0 0">
                                <inertial pos="0 0 0.0225" quat="0.707107 0 0 0.707107" mass="0.03" diaginertia="1e-05 9.8e-06 1.8e-06" />
                                <joint name="rh_LFJ3" pos="0 0 0" axis="1 0 0" limited="true" range="0 1.5708" damping="0.5" armature="0.005" margin="0.01" frictionloss="0.001"/>
                                <geom type="mesh" material="plastic" mesh="F3" contype="262144" conaffinity="15794175" />
                                <body name="rh_lfmiddle" pos="0 0 0.045">
                                    <inertial pos="0 0 0.0125" quat="0.707107 0 0 0.707107" mass="0.017" diaginertia="2.7e-06 2.6e-06 8.7e-07" />
                                    <joint name="rh_LFJ2" pos="0 0 0" axis="1 0 0" limited="true" range="0 1.5708" damping="0.5" armature="0.005" margin="0.01" frictionloss="0.001"/>
                                    <geom type="mesh" material="plastic" mesh="F2" contype="524288" conaffinity="14942207" />
                                    <body name="rh_lfdistal" pos="0 0 0.025">
                                        <inertial pos="0 0 0.012" quat="0.707107 0 0 0.707107" mass="0.012" diaginertia="1.1e-06 9.4e-07 5.3e-07" />
                                        <joint name="rh_LFJ1" pos="0 0 0" axis="1 0 0" limited="true" range="0 1.5708" damping="0.5" armature="0.005" margin="0.01" frictionloss="0.001"/>
                                        <geom type="mesh" material="plastic" mesh="F1" contype="1048576" conaffinity="15204351" />
                                        <body name="rh_lftip" pos="0 0 0.026">
                                            <inertial pos="0 0 0" mass="0.001" diaginertia="0 0 0" />
                                        </body>
                                    </body>
                                </body>
                            </body>
                        </body>
                    </body>
                    <body name="rh_thbase" pos="0.034 -0.0085 0.029" quat="0.92388 0 0.382683 0">
                        <inertial pos="0 0 0" mass="0.01" diaginertia="1.6e-07 1.6e-07 1.6e-07" />
                        <joint name="rh_THJ5" pos="0 0 0" axis="0 0 -1" limited="true" range="-1.0472 1.0472" damping="0.5" armature="0.005" margin="0.01" frictionloss="0.001"/>
                        <body name="rh_thproximal" pos="0 0 0">
                            <inertial pos="0 0 0.019" mass="0.04" diaginertia="1.36e-05 1.36e-05 3.13e-06" />
                            <joint name="rh_THJ4" pos="0 0 0" axis="1 0 0" limited="true" range="0 1.22173" damping="0.5" armature="0.005" margin="0.01" frictionloss="0.001"/>
                            <geom type="mesh" material="plastic" mesh="TH3_z" contype="2097152" conaffinity="10485751" />
                            <body name="rh_thhub" pos="0 0 0.038">
                                <inertial pos="0 0 0" mass="0.005" diaginertia="1.0e-06 1.0e-06 3.0e-07" />
                                <joint name="rh_THJ3" pos="0 0 0" axis="1 0 0" limited="true" range="-0.20944 0.20944" damping="0.5" armature="0.005" margin="0.01" frictionloss="0.001"/>
                                <body name="rh_thmiddle" pos="0 0 0">
                                    <inertial pos="0 0 0.016" mass="0.02" diaginertia="5.1e-06 5.1e-06 1.21e-06" />
                                    <joint name="rh_THJ2" pos="0 0 0" axis="0 -1 0" limited="true" range="-0.698132 0.698132" damping="0.5" armature="0.005" margin="0.01" frictionloss="0.001"/>
                                    <geom type="mesh" material="plastic" mesh="TH2_z" contype="4194304" conaffinity="2097151" />
                                    <body name="rh_thdistal" pos="0 0 0.032" quat="0.707107 0 0 -0.707107">
                                        <inertial pos="0 0 0.01375" quat="0.707107 0 0 0.707107" mass="0.016" diaginertia="2.2e-06 2.1e-06 1e-06" />
                                        <joint name="rh_THJ1" pos="0 0 0" axis="1 0 0" limited="true" range="0 1.5708" damping="0.5" armature="0.005" margin="0.01" frictionloss="0.001"/>
                                        <geom type="mesh" material="plastic" mesh="TH1_z" contype="8388608" conaffinity="4194303" />
                                        <body name="rh_thtip" pos="0 0 0.0275">
                                            <inertial pos="0 0 0" mass="0.001" diaginertia="0 0 0" />
                                        </body>
                                    </body>
                                </body>
                            </body>
                        </body>
                    </body>
                </body>
            </body>
        </body>
    </worldbody>
</mujoco>