<robot xmlns:xacro="http://ros.org/wiki/xacro"
       xmlns:sensor="http://playerstage.sourceforge.net/gazebo/xmlschema/#sensor"
       xmlns:controller="http://playerstage.sourceforge.net/gazebo/xmlschema/#controller"
       xmlns:joint="http://playerstage.sourceforge.net/gazebo/xmlschema/#slider"
       xmlns:interface="http://playerstage.sourceforge.net/gazebo/xmlschema/#interface"
       xmlns:body="http://playerstage.sourceforge.net/gazebo/xmlschema/#body"
       xmlns:geom="http://playerstage.sourceforge.net/gazebo/xmlschema/#geom">

  <include filename="$(find sr_description)/hand/xacro/thumb/thhub.transmission.xacro" />

  <xacro:macro name="thhub" params="parent">

    <link name="thhub">
      <inertial>
	<mass value="0.002" />
	<origin xyz="0 0 0" rpy="0 0 0"/>
	<inertia  ixx="0.1" ixy="0.0"  ixz="0.0"  iyy="0.1"  iyz="0.0"
	izz="0.1" />
      </inertial>
      <visual>
	<origin xyz="0 0 0" rpy="0 0 0" />
	<geometry name="thhub_visual">
	<box size="0.001 0.001 0.001" />
      </geometry>
      <material name="shadow_thhub_material">
	  <color rgba="0.7 0.7 0.7 1.0"/>
	</material>
      </visual>
      <collision>
	<origin xyz="0 0 0" rpy="0 0 0 " />
	<geometry name="thhub_collision_geom">
	  <box size="0.001 0.001 0.001" />
	</geometry>
      </collision>
    </link>
    <gazebo reference="thhub">
      <sensor:contact name="thhub_contact_sensor">
        <geom>thhub_geom</geom>
       <updateRate>100.0</updateRate>
        <controller:gazebo_ros_bumper name="thhub_gazebo_ros_bumper_controller" plugin="libgazebo_ros_bumper.so">
          <alwaysOn>true</alwaysOn>
          <updateRate>100.0</updateRate>
          <frameName>thhub</frameName>
          <bumperTopicName>thhub_bumper</bumperTopicName>
          <interface:bumper name="thhub_gazebo_ros_bumper_iface" />
        </controller:gazebo_ros_bumper>
      </sensor:contact>
      <material>Gazebo/Grey</material>
    </gazebo>

    <joint name="THJ3" type="revolute">
      <parent link="${parent}"/>
      <child link="thhub"/>
      <origin xyz="0 0 0.038" rpy="0 0 0" />
      <axis xyz="1 0 0" />
      <limit lower="-0.2618" upper="0.2618" effort="10"
      velocity="1.0" />
      <dynamics damping="50.5"/>
    </joint>

    <xacro:thhub_transmission />

  </xacro:macro>

</robot>
